2022-01-18 07:23:54 WARNING   * Running on all addresses.
   WARNING: This is a development server. Do not use it in a production deployment.
2022-01-18 07:23:54 INFO      * Running on http://192.168.1.206:3111/ (Press CTRL+C to quit)
2022-01-18 07:24:07 ERROR    Exception on /1 [GET]
Traceback (most recent call last):
  File "/Library/Frameworks/Python.framework/Versions/3.10/lib/python3.10/site-packages/flask/app.py", line 2073, in wsgi_app
    response = self.full_dispatch_request()
  File "/Library/Frameworks/Python.framework/Versions/3.10/lib/python3.10/site-packages/flask/app.py", line 1518, in full_dispatch_request
    rv = self.handle_user_exception(e)
  File "/Library/Frameworks/Python.framework/Versions/3.10/lib/python3.10/site-packages/flask/app.py", line 1516, in full_dispatch_request
    rv = self.dispatch_request()
  File "/Library/Frameworks/Python.framework/Versions/3.10/lib/python3.10/site-packages/flask/app.py", line 1502, in dispatch_request
    return self.ensure_sync(self.view_functions[rule.endpoint])(**req.view_args)
  File "/Users/nwhittington/nd064_course_1/project/techtrends/app.py", line 76, in post
    post = get_post(post_id)
  File "/Users/nwhittington/nd064_course_1/project/techtrends/app.py", line 26, in get_post
    post = connection.execute('SELECT * FROM posts WHERE id = ?',
sqlite3.OperationalError: no such table: posts
2022-01-18 07:24:07 INFO     127.0.0.1 - - [18/Jan/2022 07:24:07] "[35m[1mGET /1 HTTP/1.1[0m" 500 -
2022-01-18 07:24:11 ERROR    Exception on / [GET]
Traceback (most recent call last):
  File "/Library/Frameworks/Python.framework/Versions/3.10/lib/python3.10/site-packages/flask/app.py", line 2073, in wsgi_app
    response = self.full_dispatch_request()
  File "/Library/Frameworks/Python.framework/Versions/3.10/lib/python3.10/site-packages/flask/app.py", line 1518, in full_dispatch_request
    rv = self.handle_user_exception(e)
  File "/Library/Frameworks/Python.framework/Versions/3.10/lib/python3.10/site-packages/flask/app.py", line 1516, in full_dispatch_request
    rv = self.dispatch_request()
  File "/Library/Frameworks/Python.framework/Versions/3.10/lib/python3.10/site-packages/flask/app.py", line 1502, in dispatch_request
    return self.ensure_sync(self.view_functions[rule.endpoint])(**req.view_args)
  File "/Users/nwhittington/nd064_course_1/project/techtrends/app.py", line 44, in index
    posts = connection.execute('SELECT * FROM posts').fetchall()
sqlite3.OperationalError: no such table: posts
2022-01-18 07:24:11 INFO     127.0.0.1 - - [18/Jan/2022 07:24:11] "[35m[1mGET / HTTP/1.1[0m" 500 -
2022-01-18 07:24:14 ERROR    Exception on / [GET]
Traceback (most recent call last):
  File "/Library/Frameworks/Python.framework/Versions/3.10/lib/python3.10/site-packages/flask/app.py", line 2073, in wsgi_app
    response = self.full_dispatch_request()
  File "/Library/Frameworks/Python.framework/Versions/3.10/lib/python3.10/site-packages/flask/app.py", line 1518, in full_dispatch_request
    rv = self.handle_user_exception(e)
  File "/Library/Frameworks/Python.framework/Versions/3.10/lib/python3.10/site-packages/flask/app.py", line 1516, in full_dispatch_request
    rv = self.dispatch_request()
  File "/Library/Frameworks/Python.framework/Versions/3.10/lib/python3.10/site-packages/flask/app.py", line 1502, in dispatch_request
    return self.ensure_sync(self.view_functions[rule.endpoint])(**req.view_args)
  File "/Users/nwhittington/nd064_course_1/project/techtrends/app.py", line 44, in index
    posts = connection.execute('SELECT * FROM posts').fetchall()
sqlite3.OperationalError: no such table: posts
2022-01-18 07:24:14 INFO     127.0.0.1 - - [18/Jan/2022 07:24:14] "[35m[1mGET / HTTP/1.1[0m" 500 -
2022-01-18 07:24:42 ERROR    Exception on / [GET]
Traceback (most recent call last):
  File "/Library/Frameworks/Python.framework/Versions/3.10/lib/python3.10/site-packages/flask/app.py", line 2073, in wsgi_app
    response = self.full_dispatch_request()
  File "/Library/Frameworks/Python.framework/Versions/3.10/lib/python3.10/site-packages/flask/app.py", line 1518, in full_dispatch_request
    rv = self.handle_user_exception(e)
  File "/Library/Frameworks/Python.framework/Versions/3.10/lib/python3.10/site-packages/flask/app.py", line 1516, in full_dispatch_request
    rv = self.dispatch_request()
  File "/Library/Frameworks/Python.framework/Versions/3.10/lib/python3.10/site-packages/flask/app.py", line 1502, in dispatch_request
    return self.ensure_sync(self.view_functions[rule.endpoint])(**req.view_args)
  File "/Users/nwhittington/nd064_course_1/project/techtrends/app.py", line 44, in index
    posts = connection.execute('SELECT * FROM posts').fetchall()
sqlite3.OperationalError: no such table: posts
2022-01-18 07:24:42 INFO     127.0.0.1 - - [18/Jan/2022 07:24:42] "[35m[1mGET / HTTP/1.1[0m" 500 -
2022-01-18 07:24:49 ERROR    Exception on / [GET]
Traceback (most recent call last):
  File "/Library/Frameworks/Python.framework/Versions/3.10/lib/python3.10/site-packages/flask/app.py", line 2073, in wsgi_app
    response = self.full_dispatch_request()
  File "/Library/Frameworks/Python.framework/Versions/3.10/lib/python3.10/site-packages/flask/app.py", line 1518, in full_dispatch_request
    rv = self.handle_user_exception(e)
  File "/Library/Frameworks/Python.framework/Versions/3.10/lib/python3.10/site-packages/flask/app.py", line 1516, in full_dispatch_request
    rv = self.dispatch_request()
  File "/Library/Frameworks/Python.framework/Versions/3.10/lib/python3.10/site-packages/flask/app.py", line 1502, in dispatch_request
    return self.ensure_sync(self.view_functions[rule.endpoint])(**req.view_args)
  File "/Users/nwhittington/nd064_course_1/project/techtrends/app.py", line 44, in index
    posts = connection.execute('SELECT * FROM posts').fetchall()
sqlite3.OperationalError: no such table: posts
2022-01-18 07:24:49 INFO     127.0.0.1 - - [18/Jan/2022 07:24:49] "[35m[1mGET / HTTP/1.1[0m" 500 -
2022-01-18 07:27:18 ERROR    Exception on / [GET]
Traceback (most recent call last):
  File "/Library/Frameworks/Python.framework/Versions/3.10/lib/python3.10/site-packages/flask/app.py", line 2073, in wsgi_app
    response = self.full_dispatch_request()
  File "/Library/Frameworks/Python.framework/Versions/3.10/lib/python3.10/site-packages/flask/app.py", line 1518, in full_dispatch_request
    rv = self.handle_user_exception(e)
  File "/Library/Frameworks/Python.framework/Versions/3.10/lib/python3.10/site-packages/flask/app.py", line 1516, in full_dispatch_request
    rv = self.dispatch_request()
  File "/Library/Frameworks/Python.framework/Versions/3.10/lib/python3.10/site-packages/flask/app.py", line 1502, in dispatch_request
    return self.ensure_sync(self.view_functions[rule.endpoint])(**req.view_args)
  File "/Users/nwhittington/nd064_course_1/project/techtrends/app.py", line 44, in index
    posts = connection.execute('SELECT * FROM posts').fetchall()
sqlite3.OperationalError: no such table: posts
2022-01-18 07:27:18 INFO     127.0.0.1 - - [18/Jan/2022 07:27:18] "[35m[1mGET / HTTP/1.1[0m" 500 -
2022-01-18 07:27:20 ERROR    Exception on / [GET]
Traceback (most recent call last):
  File "/Library/Frameworks/Python.framework/Versions/3.10/lib/python3.10/site-packages/flask/app.py", line 2073, in wsgi_app
    response = self.full_dispatch_request()
  File "/Library/Frameworks/Python.framework/Versions/3.10/lib/python3.10/site-packages/flask/app.py", line 1518, in full_dispatch_request
    rv = self.handle_user_exception(e)
  File "/Library/Frameworks/Python.framework/Versions/3.10/lib/python3.10/site-packages/flask/app.py", line 1516, in full_dispatch_request
    rv = self.dispatch_request()
  File "/Library/Frameworks/Python.framework/Versions/3.10/lib/python3.10/site-packages/flask/app.py", line 1502, in dispatch_request
    return self.ensure_sync(self.view_functions[rule.endpoint])(**req.view_args)
  File "/Users/nwhittington/nd064_course_1/project/techtrends/app.py", line 44, in index
    posts = connection.execute('SELECT * FROM posts').fetchall()
sqlite3.OperationalError: no such table: posts
2022-01-18 07:27:20 INFO     127.0.0.1 - - [18/Jan/2022 07:27:20] "[35m[1mGET / HTTP/1.1[0m" 500 -
2022-01-18 07:35:38 ERROR    Exception on / [GET]
Traceback (most recent call last):
  File "/Library/Frameworks/Python.framework/Versions/3.10/lib/python3.10/site-packages/flask/app.py", line 2073, in wsgi_app
    response = self.full_dispatch_request()
  File "/Library/Frameworks/Python.framework/Versions/3.10/lib/python3.10/site-packages/flask/app.py", line 1518, in full_dispatch_request
    rv = self.handle_user_exception(e)
  File "/Library/Frameworks/Python.framework/Versions/3.10/lib/python3.10/site-packages/flask/app.py", line 1516, in full_dispatch_request
    rv = self.dispatch_request()
  File "/Library/Frameworks/Python.framework/Versions/3.10/lib/python3.10/site-packages/flask/app.py", line 1502, in dispatch_request
    return self.ensure_sync(self.view_functions[rule.endpoint])(**req.view_args)
  File "/Users/nwhittington/nd064_course_1/project/techtrends/app.py", line 44, in index
    connection = get_db_connection()
sqlite3.OperationalError: no such table: posts
2022-01-18 07:35:38 INFO     127.0.0.1 - - [18/Jan/2022 07:35:38] "[35m[1mGET / HTTP/1.1[0m" 500 -
2022-01-18 07:35:41 ERROR    Exception on / [GET]
Traceback (most recent call last):
  File "/Library/Frameworks/Python.framework/Versions/3.10/lib/python3.10/site-packages/flask/app.py", line 2073, in wsgi_app
    response = self.full_dispatch_request()
  File "/Library/Frameworks/Python.framework/Versions/3.10/lib/python3.10/site-packages/flask/app.py", line 1518, in full_dispatch_request
    rv = self.handle_user_exception(e)
  File "/Library/Frameworks/Python.framework/Versions/3.10/lib/python3.10/site-packages/flask/app.py", line 1516, in full_dispatch_request
    rv = self.dispatch_request()
  File "/Library/Frameworks/Python.framework/Versions/3.10/lib/python3.10/site-packages/flask/app.py", line 1502, in dispatch_request
    return self.ensure_sync(self.view_functions[rule.endpoint])(**req.view_args)
  File "/Users/nwhittington/nd064_course_1/project/techtrends/app.py", line 44, in index
    connection = get_db_connection()
sqlite3.OperationalError: no such table: posts
2022-01-18 07:35:41 INFO     127.0.0.1 - - [18/Jan/2022 07:35:41] "[35m[1mGET / HTTP/1.1[0m" 500 -
2022-01-18 07:36:26 ERROR    Exception on / [GET]
Traceback (most recent call last):
  File "/Library/Frameworks/Python.framework/Versions/3.10/lib/python3.10/site-packages/flask/app.py", line 2073, in wsgi_app
    response = self.full_dispatch_request()
  File "/Library/Frameworks/Python.framework/Versions/3.10/lib/python3.10/site-packages/flask/app.py", line 1518, in full_dispatch_request
    rv = self.handle_user_exception(e)
  File "/Library/Frameworks/Python.framework/Versions/3.10/lib/python3.10/site-packages/flask/app.py", line 1516, in full_dispatch_request
    rv = self.dispatch_request()
  File "/Library/Frameworks/Python.framework/Versions/3.10/lib/python3.10/site-packages/flask/app.py", line 1502, in dispatch_request
    return self.ensure_sync(self.view_functions[rule.endpoint])(**req.view_args)
  File "/Users/nwhittington/nd064_course_1/project/techtrends/app.py", line 44, in index
    connection = get_db_connection()
sqlite3.OperationalError: no such table: posts
2022-01-18 07:36:26 INFO     127.0.0.1 - - [18/Jan/2022 07:36:26] "[35m[1mGET / HTTP/1.1[0m" 500 -
2022-01-18 07:37:17 ERROR    Exception on / [GET]
Traceback (most recent call last):
  File "/Library/Frameworks/Python.framework/Versions/3.10/lib/python3.10/site-packages/flask/app.py", line 2073, in wsgi_app
    response = self.full_dispatch_request()
  File "/Library/Frameworks/Python.framework/Versions/3.10/lib/python3.10/site-packages/flask/app.py", line 1518, in full_dispatch_request
    rv = self.handle_user_exception(e)
  File "/Library/Frameworks/Python.framework/Versions/3.10/lib/python3.10/site-packages/flask/app.py", line 1516, in full_dispatch_request
    rv = self.dispatch_request()
  File "/Library/Frameworks/Python.framework/Versions/3.10/lib/python3.10/site-packages/flask/app.py", line 1502, in dispatch_request
    return self.ensure_sync(self.view_functions[rule.endpoint])(**req.view_args)
  File "/Users/nwhittington/nd064_course_1/project/techtrends/app.py", line 44, in index
    connection = get_db_connection()
sqlite3.OperationalError: no such table: posts
2022-01-18 07:37:17 INFO     127.0.0.1 - - [18/Jan/2022 07:37:17] "[35m[1mGET / HTTP/1.1[0m" 500 -
2022-01-18 07:41:07 WARNING   * Running on all addresses.
   WARNING: This is a development server. Do not use it in a production deployment.
2022-01-18 07:41:07 INFO      * Running on http://192.168.1.206:3111/ (Press CTRL+C to quit)
2022-01-18 07:42:23 WARNING   * Running on all addresses.
   WARNING: This is a development server. Do not use it in a production deployment.
2022-01-18 07:42:23 INFO      * Running on http://192.168.1.206:3111/ (Press CTRL+C to quit)
2022-01-18 07:42:39 WARNING   * Running on all addresses.
   WARNING: This is a development server. Do not use it in a production deployment.
2022-01-18 07:42:39 INFO      * Running on http://192.168.1.206:3111/ (Press CTRL+C to quit)
2022-01-18 07:42:42 ERROR    Exception on / [GET]
Traceback (most recent call last):
  File "/Library/Frameworks/Python.framework/Versions/3.10/lib/python3.10/site-packages/flask/app.py", line 2073, in wsgi_app
    response = self.full_dispatch_request()
  File "/Library/Frameworks/Python.framework/Versions/3.10/lib/python3.10/site-packages/flask/app.py", line 1518, in full_dispatch_request
    rv = self.handle_user_exception(e)
  File "/Library/Frameworks/Python.framework/Versions/3.10/lib/python3.10/site-packages/flask/app.py", line 1516, in full_dispatch_request
    rv = self.dispatch_request()
  File "/Library/Frameworks/Python.framework/Versions/3.10/lib/python3.10/site-packages/flask/app.py", line 1502, in dispatch_request
    return self.ensure_sync(self.view_functions[rule.endpoint])(**req.view_args)
  File "/Users/nwhittington/nd064_course_1/project/techtrends/app.py", line 43, in index
    posts = connection.execute('SELECT * FROM posts').fetchall()
sqlite3.OperationalError: no such table: posts
2022-01-18 07:42:42 INFO     127.0.0.1 - - [18/Jan/2022 07:42:42] "[35m[1mGET / HTTP/1.1[0m" 500 -
2022-01-18 07:42:50 ERROR    Exception on / [GET]
Traceback (most recent call last):
  File "/Library/Frameworks/Python.framework/Versions/3.10/lib/python3.10/site-packages/flask/app.py", line 2073, in wsgi_app
    response = self.full_dispatch_request()
  File "/Library/Frameworks/Python.framework/Versions/3.10/lib/python3.10/site-packages/flask/app.py", line 1518, in full_dispatch_request
    rv = self.handle_user_exception(e)
  File "/Library/Frameworks/Python.framework/Versions/3.10/lib/python3.10/site-packages/flask/app.py", line 1516, in full_dispatch_request
    rv = self.dispatch_request()
  File "/Library/Frameworks/Python.framework/Versions/3.10/lib/python3.10/site-packages/flask/app.py", line 1502, in dispatch_request
    return self.ensure_sync(self.view_functions[rule.endpoint])(**req.view_args)
  File "/Users/nwhittington/nd064_course_1/project/techtrends/app.py", line 43, in index
    posts = connection.execute('SELECT * FROM posts').fetchall()
sqlite3.OperationalError: no such table: posts
2022-01-18 07:42:50 INFO     127.0.0.1 - - [18/Jan/2022 07:42:50] "[35m[1mGET / HTTP/1.1[0m" 500 -
